Workbook
Name \0: #REF!
Name \a: #REF!
Name \b: #REF!
Name \c: #REF!
Name \charles: #REF!
Name \d: #REF!
Name \f: #N/A
Name \g: #N/A
Name \H: #REF!
Name \i: #REF!
Name \J: #REF!
Name \K: #REF!
Name \L: #REF!
Name \m: #REF!
Name \N: #REF!
Name \p: #REF!
Name \Q: #REF!
Name \r: #REF!
Name \s: #REF!
Name \u: #REF!
Name \v: #N/A
Name \x: #N/A
Name \z: #REF!
Name ___________ari2: #REF!
Name ___________ari3: #REF!
Name ___________ari4: #REF!
Name ___________ari5: #REF!
Name ___________ari6: #REF!
Name ___________ari7: #REF!
Name ___________ari8: #REF!
Name ___________m10: #REF!
Name ___________m11: #REF!
Name ___________m2: #REF!
Name ___________m3: #REF!
Name ___________m4: #REF!
Name ___________m5: #REF!
Name ___________m6: #REF!
Name ___________m7: #REF!
Name ___________m8: #REF!
Name ___________m9: #REF!
Name __________R: #REF!
Name _________ari2: #REF!
Name _________ari3: #REF!
Name _________ari4: #REF!
Name _________ari5: #REF!
Name _________ari6: #REF!
Name _________ari7: #REF!
Name _________ari8: #REF!
Name _________m10: #REF!
Name _________m11: #REF!
Name _________m2: #REF!
Name _________m3: #REF!
Name _________m4: #REF!
Name _________m5: #REF!
Name _________m6: #REF!
Name _________m7: #REF!
Name _________m8: #REF!
Name _________m9: #REF!
Name _______ari2: #REF!
Name _______ari3: #REF!

Sheet Azzas 2154
B1: Azzas 2154
B2: Dados financeiros e operacionais
B3: Financial and operating data

Sheet Revenue per BU and channel
C2: Revenue per BU and channel
B4: Português | C4: English | D4: 1Q22 | E4: 2Q22 | F4: 3Q22 | G4: 4Q22 | H4: 1Q23 | I4: 2Q23 | J4: 3Q23 | K4: 4Q23 | L4: 1Q24 | M4: 2Q24 | N4: 3Q24 | O4: 4Q24 | P4: 1Q25 | Q4: 2Q25 | R4: 3Q25 | T4: CQGR | V4: 4Q25 | W4: 1Q26 | X4: 2Q26 | Y4: 3Q26 | Z4: 4Q26 | AA4: 1Q27 | AB4: 2Q27 | AC4: 3Q27 | AD4: 4Q27 | AE4: 1Q28 | AF4: 2Q28 | AG4: 3Q28 | AH4: 4Q28 | AI4: 1Q29 | AJ4: 2Q29 | AK4: 3Q25 | AL4: 4Q29 | AM4: 1Q30 | AN4: 2Q30 | AO4: 3Q30 | AP4: 4Q30 | AQ4: 1Q31 | AR4: 2Q31 | AS4: 3Q31 | AT4: 4Q31
B6: Receita por Businness Unit | C6: Revenue per Business Unit | D6: 2271.3 | E6: 2613.5 | F6: 2969.4 | G6: 3306.3 | H6: 2789.9 | I6: 3047.9 | J6: 3274.3 | K6: 3667.3 | L6: 2894.1 | M6: 3370.5 | N6: 3673.5 | O6: 4221.6 | P6: 3311.8 | Q6: 3620 | R6: 3716.2
B7: Operações Continuadas | C7: Continued Operations | D7: 2210.3 | E7: 2538.2 | F7: 2890.4 | G7: 3218.2 | H7: 2700 | I7: 2945.6 | J7: 3173.3 | K7: 3554.7 | L7: 2807.8 | M7: 3269.5 | N7: 3558.7 | O7: 4094.7 | P7: 3260.3 | Q7: 3606.2 | R7: 3714.7
B8: Shoes & Bags | C8: Shoes & Bags | D8: 813.7 | E8: 867.8 | F8: 1048.3 | G8: 1108.9 | H8: 943.4 | I8: 1002.9 | J8: 1153.9 | K8: 1215 | L8: 991 | M8: 1095.2 | N8: 1186 | O8: 1263.5 | P8: 1038.2 | Q8: 1103.3 | R8: 1119.2
B9: Fashion & Lifestyle Women | C9: Fashion & Lifestyle Women | D9: 706.4 | E9: 874.1 | F9: 963.6 | G9: 978.4 | H9: 915.9 | I9: 1028.6 | J9: 1053.4 | K9: 1088.9 | L9: 979.4 | M9: 1202.9 | N9: 1239.2 | O9: 1341.4 | P9: 1244.5 | Q9: 1444.9 | R9: 1465.3
B10: Fashion & Lifestyle Men | C10: Fashion & Lifestyle Men | D10: 203.4 | E10: 260.9 | F10: 312.6 | G10: 476.1 | H10: 294.7 | I10: 337 | J10: 374.1 | K10: 538.1 | L10: 320.3 | M10: 377.7 | N10: 466.3 | O10: 643.6 | P10: 360.7 | Q10: 421.3 | R10: 491.4
B11: Basic | C11: Basic | D11: 485.4 | E11: 534.8 | F11: 558.3 | G11: 661.3 | H11: 544 | I11: 574.4 | J11: 591.2 | K11: 712.3 | L11: 515.9 | M11: 593.4 | N11: 666.9 | O11: 844.1 | P11: 616.1 | Q11: 636.5 | R11: 638.8
B12: Outros | C12: Other | D12: 1.4 | E12: 0.6 | F12: 7.6 | G12: -6.5 | H12: 2 | I12: 2.7 | J12: 0.7 | K12: 0.4 | L12: 1.2 | M12: 0.3 | N12: 0.3 | O12: 2.1 | P12: 0.8 | Q12: 0.2 | R12: 0
B13: Operações Descontinuadas | C13: Discontinued Operations | D13: 61 | E13: 75.3 | F13: 79 | G13: 88.1 | H13: 89.9 | I13: 102.3 | J13: 101 | K13: 112.6 | L13: 86.3 | M13: 101 | N13: 114.8 | O13: 126.9 | P13: 51.5 | Q13: 13.8 | R13: 1.5
B15: Receita por Canal | C15: Revenue per Channel | D15: 2271.3 | E15: 2613.5 | F15: 2969.4 | G15: 3306.3 | H15: 2789.9 | I15: 3047.9 | J15: 3274.3 | K15: 3667.3 | L15: 2894.1 | M15: 3370.5 | N15: 3673.5 | O15: 4221.6 | P15: 3311.8 | Q15: 3620 | R15: 3716.2
B16: Operações Continuadas | C16: Continued Operations | D16: 2210.3 | E16: 2538.2 | F16: 2890.4 | G16: 3218.2 | H16: 2700 | I16: 2945.6 | J16: 3173.3 | K16: 3554.7 | L16: 2807.8 | M16: 3269.5 | N16: 3558.7 | O16: 4094.7 | P16: 3260.3 | Q16: 3606.2 | R16: 3714.7
B17: Sell-Out | C17: Sell-Out | D17: 1014.8 | E17: 1183.8 | F17: 1269.4 | G17: 1640.8 | H17: 1219 | I17: 1374.7 | J17: 1438.5 | K17: 1936.7 | L17: 1374.5 | M17: 1595.9 | N17: 1709.6 | O17: 2280.9 | P17: 1610.3 | Q17: 1781.3 | R17: 1816.3
B18: Lojas próprias | C18: Owned Stores | D18: 585.4 | E18: 751 | F18: 760.3 | G18: 1047.1 | H18: 731.2 | I18: 862.7 | J18: 857.9 | K18: 1190.9 | L18: 826.1 | M18: 985.6 | N18: 1012.3 | O18: 1419.4 | P18: 998.5 | Q18: 1129.9 | R18: 1082.5
... B28: Operações Continuadas | C28: Continued Operations | D28: 813.7 | E28: 867.8 | F28: 1048.3 | G28: 1108.9 | H28: 943.4 | I28: 1002.9 | J28: 1153.9 | K28: 1215 | L28: 991 | M28: 1095.2 | N28: 1186 | O28: 1263.5 | P28: 1038.2 | Q28: 1103.3 | R28: 1119.2
B29: Sell-Out | C29: Sell-Out | D29: 258.5 | E29: 315.1 | F29: 335.9 | G29: 384.5 | H29: 315.7 | I29: 361.5 | J29: 380.3 | K29: 455.9 | L29: 373.6 | M29: 414.1 | N29: 426.1 | O29: 493 | P29: 399.5 | Q29: 432.7 | R29: 420.2 | T29: =IFERROR(((R29/D29)^(1/15)-1),"N/A") -> 0.032919239 | V29: =R29*(1+T29) -> 434.03266
B30: Lojas próprias | C30: Owned Stores | D30: 88.8 | E30: 132.4 | F30: 120.2 | G30: 165.6 | H30: 125.5 | I30: 164.4 | J30: 148.1 | K30: 204.1 | L30: 142.4 | M30: 178.3 | N30: 176 | O30: 229.4 | P30: 160.9 | Q30: 187.4 | R30: 172.8
B31: E-commerce | C31: E-commerce | D31: 169.7 | E31: 182.7 | F31: 215.7 | G31: 218.9 | H31: 190.2 | I31: 197.1 | J31: 232.2 | K31: 251.8 | L31: 231.2 | M31: 235.8 | N31: 250.1 | O31: 263.6 | P31: 238.6 | Q31: 245.3 | R31: 247.4
B32: Sell-In | C32: Sell-In | D32: 430.1 | E32: 423.1 | F32: 570.4 | G32: 569.1 | H32: 521.8 | I32: 530.3 | J32: 639.7 | K32: 636.8 | L32: 520.9 | M32: 564.2 | N32: 627.2 | O32: 637.6 | P32: 515.7 | Q32: 556 | R32: 566.4 | T32: =IFERROR(((R32/D32)^(1/15)-1),"N/A") -> 0.018521623 | V32: =R32*(1+T32) -> 576.89065
B33: Franquia | C33: Franchises | D33: 237 | E33: 237.8 | F33: 288.4 | G33: 305.4 | H33: 275.3 | I33: 278 | J33: 313.4 | K33: 326.3 | L33: 268.4 | M33: 275.7 | N33: 305.3 | O33: 350.4 | P33: 260.6 | Q33: 267.4 | R33: 262
B34: Multimarcas | C34: Multibrand | D34: 193.1 | E34: 185.3 | F34: 282 | G34: 263.7 | H34: 246.5 | I34: 252.3 | J34: 326.3 | K34: 310.5 | L34: 252.5 | M34: 288.5 | N34: 321.9 | O34: 287.2 | P34: 255.1 | Q34: 288.6 | R34: 304.4
B35: Internacional | C35: International | D35: 119.9 | E35: 125.9 | F35: 137 | G35: 151 | H35: 104 | I35: 102.6 | J35: 123 | K35: 100.1 | L35: 86.3 | M35: 103.2 | N35: 120.2 | O35: 117 | P35: 111.5 | Q35: 99.5 | R35: 121.9 | T35: =IFERROR(((R35/D35)^(1/15)-1),"N/A") -> 0.0011034733 | V35: =R35*(1+T35) -> 122.03451
B36: Outros | C36: Other | D36: 5.2 | E36: 3.7 | F36: 5 | G36: 4.3 | H36: 1.9 | I36: 8.5 | J36: 10.9 | K36: 22.2 | L36: 10.2 | M36: 13.7 | N36: 12.5 | O36: 15.9 | P36: 11.5 | Q36: 15.1 | R36: 10.7 | T36: =IFERROR(((R36/D36)^(1/15)-1),"N/A") -> 0.049281532 | V36: =R36*(1+T36) -> 11.227312
B37: Operações Descontinuadas | C37: Discontinued Operations | D37: 17.3 | E37: 25.4 | F37: 30.5 | G37: 28.6 | H37: 29.9 | I37: 42.9 | J37: 33.3 | K37: 30.2 | L37: 20.5 | M37: 32.1 | N37: 30.4 | O37: 32.5 | P37: 1.2 | Q37: 1.6 | R37: -1.1
B39: Fashion Women | C39: Fashion Women | D39: 706.4 | E39: 874.1 | F39: 963.6 | G39: 978.4 | H39: 915.9 | I39: 1028.6 | J39: 1053.4 | K39: 1088.9 | L39: 979.4 | M39: 1202.9 | N39: 1239.2 | O39: 1341.4 | P39: 1244.5 | Q39: 1444.9 | R39: 1465.3
B40: Operações Continuadas | C40: Continued Operations | D40: 706.4 | E40: 874.1 | F40: 963.6 | G40: 978.4 | H40: 915.9 | I40: 1028.6 | J40: 1053.4 | K40: 1088.9 | L40: 979.4 | M40: 1202.9 | N40: 1239.2 | O40: 1341.4 | P40: 1244.5 | Q40: 1444.9 | R40: 1465.3
B41: Sell-Out | C41: Sell-Out | D41: 464.8 | E41: 516 | F41: 562.2 | G41: 667.1 | H41: 537.2 | I41: 584.2 | J41: 586 | K41: 733.2 | L41: 589.2 | M41: 680.5 | N41: 690 | O41: 893.8 | P41: 705.7 | Q41: 787.1 | R41: 785.4 | T41: =IFERROR(((R41/D41)^(1/15)-1),"N/A") -> 0.035591122 | V41: =R41*(1+T41) -> 813.35327
B42: Lojas próprias | C42: Owned Stores | D42: 309.1 | E42: 370.2 | F42: 388.3 | G42: 480.8 | H42: 377.6 | I42: 422.2 | J42: 410.5 | K42: 521 | L42: 429.4 | M42: 500 | N42: 493.1 | O42: 642.6 | P42: 528.8 | Q42: 580.4 | R42: 550.3
B43: E-commerce | C43: E-commerce | D43: 155.7 | E43: 145.8 | F43: 173.9 | G43: 186.3 | H43: 159.6 | I43: 162 | J43: 175.5 | K43: 212.2 | L43: 159.8 | M43: 180.5 | N43: 196.9 | O43: 251.2 | P43: 176.9 | Q43: 206.7 | R43: 235.1
B44: Sell-In | C44: Sell-In | D44: 147.1 | E44: 169.6 | F44: 225 | G44: 164.4 | H44: 210.6 | I44: 200.4 | J44: 263.7 | K44: 177.9 | L44: 185.7 | M44: 222.8 | N44: 269 | O44: 197.4 | P44: 289.1 | Q44: 245.7 | R44: 333.4 | T44: =IFERROR(((R44/D44)^(1/15)-1),"N/A") -> 0.056063894 | V44: =R44*(1+T44) -> 352.0917 | W44: =V44*(1+$T$44) -> 371.83133 | X44: =W44*(1+$T$44) -> 392.67765 | Y44: =X44*(1+$T$44) -> 414.69269 | Z44: =Y44*(1+$T$44) -> 437.94197 | AA44: =Z44*(1+$T$44) -> 462.4947 | AB44: =AA44*(1+$T$44) -> 488.42396 | AC44: =AB44*(1+$T$44) -> 515.80691 | AD44: =AC44*(1+$T$44) -> 544.72505 | ... AT44: =AS44*(1+$T$44) -> 1303.8285
B45: Franquia | C45: Franchises | D45: 3 | E45: 3 | F45: 4 | G45: 4.7 | H45: 3.8 | I45: 2.6 | J45: 4.3 | K45: 4.5 | L45: 2.5 | M45: 2.2 | N45: 2.9 | O45: 2.3 | P45: 1.8 | Q45: 2.4 | R45: 3.7
B46: Multimarcas | C46: Multibrand | D46: 144.1 | E46: 166.6 | F46: 221 | G46: 159.7 | H46: 206.8 | I46: 197.8 | J46: 259.4 | K46: 173.4 | L46: 183.2 | M46: 220.6 | N46: 266.1 | O46: 195.1 | P46: 287.3 | Q46: 243.3 | R46: 329.7
B47: Internacional | C47: International | D47: 93.6 | E47: 178.9 | F47: 161 | G47: 146 | H47: 165.7 | I47: 244.3 | J47: 194.8 | K47: 170.5 | L47: 203.1 | M47: 294.7 | N47: 260.4 | O47: 237.5 | P47: 236.9 | Q47: 398.8 | R47: 366.1 | T47: =IFERROR(((R47/D47)^(1/15)-1),"N/A") -> 0.095186946 | V47: =R47*(1+T47) -> 400.94794 | W47: =V47*(1+$T$47) -> 439.11295 | X47: =W47*(1+$T$47) -> 480.91077 | Y47: =X47*(1+$T$47) -> 526.6872 | Z47: =Y47*(1+$T$47) -> 576.82095 | AA47: =Z47*(1+$T$47) -> 631.72677 | AB47: =AA47*(1+$T$47) -> 691.85891 | AC47: =AB47*(1+$T$47) -> 757.71485 | AD47: =AC47*(1+$T$47) -> 829.83941 | ... AT47: =AS47*(1+$T$47) -> 3554.7265
B48: Outros | C48: Other | D48: 0.9 | E48: 9.6 | F48: 15.4 | G48: 0.9 | H48: 2.4 | I48: -0.3 | J48: 8.9 | K48: 7.3 | L48: 1.4 | M48: 4.9 | N48: 19.8 | O48: 12.7 | P48: 12.8 | Q48: 13.3 | R48: -19.6 | T48: =IFERROR(((R48/D48)^(1/15)-1),"N/A") -> -2.2280072 | V48: =-R48*(1+T48) -> -24.068941 | W48: =-V48*(1+$T$48) -> -29.556832 | X48: =-W48*(1+$T$48) -> -36.296001 | Y48: =-X48*(1+$T$48) -> -44.57175 | Z48: =-Y48*(1+$T$48) -> -54.734429 | AA48: =-Z48*(1+$T$48) -> -67.214272 | AB48: =-AA48*(1+$T$48) -> -82.539608 | AC48: =-AB48*(1+$T$48) -> -101.35923 | AD48: =-AC48*(1+$T$48) -> -124.46986 | ... AT48: =-AS48*(1+$T$48) -> -3328.7308
B49: Operações Descontinuadas | C49: Discontinued Operations | D49: 0 | E49: 0 | F49: 0 | G49: 0 | H49: 0 | I49: 0 | J49: 0 | K49: 0 | L49: 0 | M49: 0 | N49: 0 | O49: 0 | P49: 0 | Q49: 0 | R49: 0
B51: Fashion Men | C51: Fashion Men | D51: 214.6 | E51: 273.7 | F51: 321.8 | G51: 495.4 | H51: 308.7 | I51: 360.6 | J51: 402.5 | K51: 575.8 | L51: 343.3 | M51: 407.6 | N51: 504.6 | O51: 692.2 | P51: 388.1 | Q51: 430.5 | R51: 492.8
B52: Operações Continuadas | C52: Continued Operations | D52: 203.4 | E52: 260.9 | F52: 312.6 | G52: 476.1 | H52: 294.7 | I52: 337 | J52: 374.1 | K52: 538.1 | L52: 320.3 | M52: 377.7 | N52: 466.3 | O52: 643.6 | P52: 360.7 | Q52: 421.3 | R52: 491.4
B53: Sell-Out | C53: Sell-Out | D53: 144.8 | E53: 183.3 | F53: 204 | G53: 356.4 | H53: 198.2 | I53: 243.4 | J53: 269.3 | K53: 450.8 | L53: 225.5 | M53: 286.9 | N53: 331.3 | O53: 522.1 | P53: 257.8 | Q53: 302.7 | R53: 346.9 | T53: =IFERROR(((R53/D53)^(1/15)-1),"N/A") -> 0.059975228 | V53: =R53*(1+T53) -> 367.70541 | W53: =V53*(1+$T$53) -> 389.75862 | X53: =W53*(1+$T$53) -> 413.13448 | Y53: =X53*(1+$T$53) -> 437.91232 | Z53: =Y53*(1+$T$53) -> 464.17621 | AA53: =Z53*(1+$T$53) -> 492.01529 | AB53: =AA53*(1+$T$53) -> 521.52401 | AC53: =AB53*(1+$T$53) -> 552.80254 | AD53: =AC53*(1+$T$53) -> 585.95699 | ... AT53: =AS53*(1+$T$53) -> 1487.9804
B54: Lojas próprias | C54: Owned Stores | D54: 104.9 | E54: 139 | F54: 152.5 | G54: 241.9 | H54: 120.9 | I54: 156.8 | J54: 178.7 | K54: 264.7 | L54: 142.9 | M54: 182.8 | N54: 207.4 | O54: 324.7 | P54: 167.3 | Q54: 207.5 | R54: 224.2
B55: E-commerce | C55: E-commerce | D55: 39.9 | E55: 44.3 | F55: 51.5 | G55: 114.5 | H55: 77.3 | I55: 86.6 | J55: 90.6 | K55: 186.1 | L55: 82.6 | M55: 104.1 | N55: 123.9 | O55: 197.4 | P55: 90.5 | Q55: 95.2 | R55: 122.7
...

Sheet P&L Pro Forma
C2: P&L Pro Forma
B4: Português | C4: English | D4: 1Q22 | E4: 2Q22 | F4: 3Q22 | G4: 4Q22 | H4: 1Q23 | I4: 2Q23 | J4: 3Q23 | K4: 4Q23 | L4: 1Q24 | M4: 2Q24 | N4: 3Q24 | O4: 4Q24 | P4: 1Q25 | Q4: 2Q25 | R4: 3Q25
B5: Receita Bruta | C5: Gross Revenue | D5: 2271.3 | E5: 2613.5 | F5: 2969.5 | G5: 3306.3 | H5: 2789.9 | I5: 3047.9 | J5: 3274.3 | K5: 3667.3 | L5: 2894.1 | M5: 3370.5 | N5: 3673.5 | O5: 4221.7 | P5: 3311.8 | Q5: 3620 | R5: 3718.3
B6: Deduções | C6: Deductions | D6: -354.6 | E6: -402.7 | F6: -466.4 | G6: -557 | H6: -492 | I6: -551.2 | J6: -559.6 | K6: -666 | L6: -527 | M6: -601.2 | N6: -635.3 | O6: -817.8 | P6: -615.3 | Q6: -718.6 | R6: -760.1
B7: Receita Líquida | C7: Net Revenue | D7: 1916.7 | E7: 2210.8 | F7: 2503.1 | G7: 2749.3 | H7: 2297.9 | I7: 2496.7 | J7: 2714.7 | K7: 3001.3 | L7: 2367.1 | M7: 2769.3 | N7: 3038.2 | O7: 3403.9 | P7: 2696.5 | Q7: 2901.4 | R7: 2958.2
B8: Custo da Mercadoria Vendida (CMV) | C8: Cost of Goods Sold (COGS) | D8: -889.6 | E8: -951.9 | F8: -1132.9 | G8: -1292 | H8: -1057.9 | I8: -1119.6 | J8: -1226.7 | K8: -1365.3 | L8: -1081.2 | M8: -1216 | N8: -1386.7 | O8: -1575.4 | P8: -1219.7 | Q8: -1280.9 | R8: -1356.8
B9: CMV (ex. D&A) | C9: COGS (ex. D&A) | D9: -881.1 | E9: -943.2 | F9: -1123.9 | G9: -1282.6 | H9: -1048.9 | I9: -1110.5 | J9: -1217.7 | K9: -1356.3 | L9: -1071.6 | M9: -1206.3 | N9: -1376.5 | O9: -1564.1 | P9: -1209.2 | Q9: -1271.2 | R9: -1346.4
B10: CMV (ex. D&A ex. IFRS-16) | C10: COGS (ex. D&A ex. IFRS-16) | D10: -882.3 | E10: -944.4 | F10: -1125.1 | G10: -1283.7 | H10: -1050 | I10: -1111.6 | J10: -1218.9 | K10: -1357.2 | L10: -1072.9 | M10: -1207.6 | N10: -1377.8 | O10: -1565.4 | P10: -1210.5 | Q10: -1272.5 | R10: -1347.7
B11: Arrendamentos (Impacto IFRS-16) | C11: Leases (IFRS-16 Impact) | D11: 1.2 | E11: 1.2 | F11: 1.2 | G11: 1.1 | H11: 1.1 | I11: 1.1 | J11: 1.2 | K11: 0.9 | L11: 1.3 | M11: 1.3 | N11: 1.3 | O11: 1.3 | P11: 1.3 | Q11: 1.3 | R11: 1.3
B12: Depreciação e Amortização | C12: Depreciation and Amortization | D12: -8.5 | E12: -8.7 | F12: -9 | G12: -9.4 | H12: -9 | I12: -9.1 | J12: -9 | K12: -9 | L12: -9.6 | M12: -9.7 | N12: -10.2 | O12: -11.3 | P12: -10.5 | Q12: -9.7 | R12: -10.4
B13: Lucro Bruto | C13: Gross Profit | D13: 1027.1 | E13: 1258.9 | F13: 1370.2 | G13: 1457.3 | H13: 1240 | I13: 1377.1 | J13: 1488 | K13: 1636 | L13: 1285.9 | M13: 1553.3 | N13: 1651.5 | O13: 1828.5 | P13: 1476.8 | Q13: 1620.5 | R13: 1601.4
B14: Despesa Total | C14: Total Expenses | D14: -804.1 | E14: -965.4 | F14: -1059.4 | G14: -1175.3 | H14: -1040.3 | I14: -1092.6 | J14: -1166.5 | K14: -4248.3 | L14: -1096.9 | M14: -1271.6 | N14: -1277.2 | O14: -2041.9 | P14: -1200.7 | Q14: -1258.6 | R14: -1336.6
B15: Despesas | C15: Expenses | D15: -718.1 | E15: -874.3 | F15: -976.4 | G15: -1046.9 | H15: -932.3 | I15: -970.2 | J15: -1041.3 | K15: -1168.6 | L15: -967.7 | M15: -1136.3 | N15: -1130.5 | O15: -1885.8 | P15: -1048.6 | Q15: -1104.8 | R15: -1155.3
B16: Fixas | C16: Fixed | D16: -349 | E16: -384.8 | F16: -419.8 | G16: -449.6 | H16: -405 | I16: -401.6 | J16: -460.5 | K16: -453.6 | L16: -446.8 | M16: -503.1 | N16: -525.7 | O16: -632.6 | P16: -481.3 | Q16: -473.6 | R16: -435.4
... B35: Margem Líquida | C35: Net Margin | D35: 0.082 | E35: 0.115 | F35: 0.088 | G35: 0.073 | H35: 0.057 | I35: 0.082 | J35: 0.087 | K35: -0.569 | L35: 0.034 | M35: 0.038 | N35: 0.027 | O35: -0.02 | P35: 0.044 | Q35: 0.185 | R35: 0.056

Sheet P&L Accounting
C2: P&L Accounting
B4: Português | C4: English | D4: 1Q22 | E4: 2Q22 | F4: 3Q22 | G4: 4Q22 | H4: 1Q23 | I4: 2Q23 | J4: 3Q23 | K4: 4Q23 | L4: 1Q24 | M4: 2Q24 | N4: 3Q24 | O4: 4Q24 | P4: 1Q25 | Q4: 2Q25 | R4: 3Q25
B5: Receita Líquida | C5: Net operating revenue | D5: 839.576 | E5: 944.752 | F5: 1137.985 | G5: 1311.413 | H5: 1025.291 | I5: 1131.023 | J5: 1265.823 | K5: 1424.631 | L5: 1072.182 | M5: 1357.108 | N5: 2546.621 | O5: 3403.842 | P5: 2696.5 | Q5: 2901.4 | R5: 2958.2
B6: Custo da mercadoria vendida | C6: Cost of goods sold | D6: -390.836 | E6: -416.145 | F6: -536.683 | G6: -606.428 | H6: -488.467 | I6: -516.509 | J6: -585.097 | K6: -627.634 | L6: -505.325 | M6: -681.46 | N6: -1152.465 | O6: -1575.442 | P6: -1219.7 | Q6: -1280.9 | R6: -1356.8
B7: Lucro Bruto | C7: Gross profit | D7: 448.74 | E7: 528.607 | F7: 601.302 | G7: 704.985 | H7: 536.824 | I7: 614.514 | J7: 680.726 | K7: 796.997 | L7: 566.857 | M7: 675.648 | N7: 1394.156 | O7: 1828.4 | P7: 1476.8 | Q7: 1620.5 | R7: 1601.4
B8: Receitas (despesas) operacionais | C8: Operating income (expenses) | D8: -287.588 | E8: -405.685 | F8: -474.127 | G8: -566.105 | H8: -432 | I8: -489.046 | J8: -505.521 | K8: -643.71 | L8: -459.688 | M8: -542.317 | N8: -1037.62 | O8: -2041.797 | P8: -1200.747 | Q8: -1258.6 | R8: -1336.6
B9: Comerciais | C9: Selling expenses | D9: -289.081 | E9: -333.615 | F9: -394.178 | G9: -472.497 | H9: -347.5 | I9: -401.33 | J9: -428.176 | K9: -536.626 | L9: -372.3 | M9: -443.9 | N9: -945.3 | O9: -1080.044 | P9: -911.602 | Q9: -881.3 | R9: -1000.4
B10: Administrativas e gerais | C10: General and administrative expenses | D10: -73.816 | E10: -73.402 | F10: -78.85 | G10: -104.172 | H10: -82.774 | I10: -88.527 | J10: -107.158 | K10: -117.113 | L10: -92.5 | M10: -105.2 | N10: -264 | O10: -595.385 | P10: -325.086 | Q10: -386.8 | R10: -359.9
B11: Outras despesas líquidas | C11: Other expenses, net | D11: 75.309 | E11: 1.332 | F11: -1.099 | G11: 10.564 | H11: -1.726 | I11: 0.811 | J11: 29.813 | K11: 10.029 | L11: 5.1 | M11: 6.8 | N11: 171.6 | O11: -366.368 | P11: 36.041 | Q11: 9.5 | R11: 23.7
B12: EBIT | C12: EBIT | D12: 161.152 | E12: 122.922 | F12: 127.175 | G12: 138.88 | H12: 104.824 | I12: 125.468 | J12: 175.205 | K12: 153.287 | L12: 107.169 | M12: 133.331 | N12: 356.536 | O12: -213.397 | P12: 276.054 | Q12: 361.905 | R12: 264.8
B13: Resultado Financeiro | C13: Financial income | D13: -20.407 | E13: -6.655 | F13: -12.48 | G13: -37.716 | H13: -39.591 | I13: -43.674 | J13: -48.113 | K13: -51.465 | L13: -47.621 | M13: -44.138 | N13: -145.087 | O13: -156.851 | P13: -157.732 | Q13: -201.7 | R13: -208.7
B14: EBT | C14: EBT | D14: 140.745 | E14: 116.267 | F14: 114.695 | G14: 101.164 | H14: 65.233 | I14: 81.794 | J14: 127.092 | K14: 101.822 | L14: 59.548 | M14: 89.193 | N14: 211.449 | O14: -370.248 | P14: 118.422 | Q14: 160.152 | R14: 56.1
B15: IRPJ e CSLL | C15: Income tax and social contribution | D15: -43.46 | E15: 3.554 | F15: -15.846 | G15: 5.419 | H15: -1.848 | I15: 18.668 | J15: -13.434 | K15: 19.346 | L15: 12.014 | M15: 38.717 | N15: -4.471 | O15: 302.347 | P15: -0.596 | Q15: 377.502 | R15: 108.819
B16: Corrente | C16: Current | D16: -39.603 | E16: -11.137 | F16: -14.267 | G16: -16.391 | H16: -10.947 | I16: -8.835 | J16: -41.422 | K16: 6.704 | L16: -13.781 | M16: 5.299 | N16: -3.17 | O16: 77.229 | P16: -9.531 | Q16: -1.29 | R16: 20.566
... B18: Lucro (Prejuízo) | C18: Profit (Loss) | D18: 97.285 | E18: 119.821 | F18: 98.849 | G18: 106.583 | H18: 63.385 | I18: 100.462 | J18: 113.658 | K18: 121.168 | L18: 71.562 | M18: 127.91 | N18: 206.978 | O18: -67.901 | P18: 117.826 | Q18: 537.654 | R18: 164.919

Sheet CAPEX
C2: CAPEX
B4: Português | C4: English | D4: 1Q22 | E4: 2Q22 | F4: 3Q22 | G4: 4Q22 | H4: 1Q23 | I4: 2Q23 | J4: 3Q23 | K4: 4Q23 | L4: 1Q24 | M4: 2Q24 | N4: 3Q24 | O4: 4Q24 | P4: 1Q25 | Q4: 2Q25 | R4: 3Q25 | T4: CQGR | V4: Average | X4: 4Q25 | Y4: 1Q26 | Z4: 2Q26 | AA4: 3Q26 | AB4: 4Q26 | AC4: 1Q27 | AD4: 2Q27 | AE4: 3Q27 | AF4: 4Q27 | AG4: 1Q28 | AH4: 2Q28 | AI4: 3Q28 | AJ4: 4Q28 | AK4: 1Q29 | AL4: 2Q29 | AM4: 3Q25 | AN4: 4Q29 | AO4: 1Q30 | AP4: 2Q30 | AQ4: 3Q30 | AR4: 4Q30 | AS4: 1Q31 | AT4: 2Q31 | AU4: 3Q31 | AV4: 4Q31 | AX4: Average
B5: CAPEX total | C5: Total CAPEX | D5: 69.6 | E5: 113.4 | F5: 109.7 | G5: 150.3 | H5: 100.8 | I5: 129.1 | J5: 120.4 | K5: 152 | L5: 95.7 | M5: 124.4 | N5: 139.1 | O5: 195.2 | P5: 84.4 | Q5: 94.2 | R5: 109.1 | V5: =SUM(V6:V8) -> 119.16 | W5: =AVERAGE(D5:R5) -> 119.16 | X5: =SUM(X6:X8) -> 112.58686 | Y5: =SUM(Y6:Y8) -> 116.20587 | Z5: =SUM(Z6:Z8) -> 119.9624 | AA5: =SUM(AA6:AA8) -> 123.86207 | AB5: =SUM(AB6:AB8) -> 127.91072 | AC5: =SUM(AC6:AC8) -> 132.11447 | AD5: =SUM(AD6:AD8) -> 136.47969 | AE5: =SUM(AE6:AE8) -> 141.01302 | ... AV5: =SUM(AV6:AV8) -> 251.86519 | AX5: =SUM(AX6:AX8) -> 186.50588
B6: Corporativo | C6: Corporate | D6: 40.6 | E6: 52.9 | F6: 48.3 | G6: 79.7 | H6: 65.5 | I6: 77.2 | J6: 59.8 | K6: 70.4 | L6: 47.5 | M6: 61.6 | N6: 69.2 | O6: 73 | P6: 46.5 | Q6: 60.7 | R6: 59.9 | T6: =((R6/D6)^(1/15))-1 -> 0.026266264 | V6: =AVERAGE(D6:R6) -> 60.853333 | X6: =R6*(1+T6) -> 61.473349 | Y6: =X6*(1+$T$6) -> 63.088024 | Z6: =Y6*(1+$T$6) -> 64.745111 | AA6: =Z6*(1+$T$6) -> 66.445723 | AB6: =AA6*(1+$T$6) -> 68.191004 | AC6: =AB6*(1+$T$6) -> 69.982127 | AD6: =AC6*(1+$T$6) -> 71.820296 | AE6: =AD6*(1+$T$6) -> 73.706747 | AF6: =AE6*(1+$T$6) -> 75.642748 | ... AV6: =AU6*(1+$T$6) -> 114.53234 | AX6: =AVERAGE(AF6:AT6) -> 91.265999
B7: Lojas - expansão e reformas | C7: Stores - expansion and refurbishing | D7: 20.3 | E7: 44.2 | F7: 35.7 | G7: 53.1 | H7: 14.1 | I7: 46.8 | J7: 42.7 | K7: 59.5 | L7: 28.4 | M7: 43.1 | N7: 46.8 | O7: 92.5 | P7: 21.4 | Q7: 21.2 | R7: 40.6 | T7: =((R7/D7)^(1/15))-1 -> 0.047294123 | V7: =AVERAGE(D7:R7) -> 40.693333 | X7: =R7*(1+T7) -> 42.520141 | Y7: =X7*(1+$T$7) -> 44.531094 | Z7: =Y7*(1+$T$7) -> 46.637153 | AA7: =Z7*(1+$T$7) -> 48.842816 | AB7: =AA7*(1+$T$7) -> 51.152795 | AC7: =AB7*(1+$T$7) -> 53.572021 | AD7: =AC7*(1+$T$7) -> 56.105663 | AE7: =AD7*(1+$T$7) -> 58.759131 | AF7: =AE7*(1+$T$7) -> 61.538093 | ... AV7: =AU7*(1+$T$7) -> 128.89697 | AX7: =AVERAGE(AF7:AT7) -> 86.745229
B8: Outros | C8: Other | D8: 8.7 | E8: 16.3 | F8: 25.7 | G8: 17.5 | H8: 21.2 | I8: 5.1 | J8: 17.9 | K8: 22.1 | L8: 19.8 | M8: 19.7 | N8: 23.1 | O8: 29.7 | P8: 16.5 | Q8: 12.3 | R8: 8.6 | T8: =((R8/D8)^(1/15))-1 -> -0.00077042456 | V8: =AVERAGE(D8:R8) -> 17.613333 | X8: =R8*(1+T8) -> 8.5933743 | Y8: =X8*(1+$T$8) -> 8.5867538 | Z8: =Y8*(1+$T$8) -> 8.5801384 | AA8: =Z8*(1+$T$8) -> 8.573528 | AB8: =AA8*(1+$T$8) -> 8.5669228 | AC8: =AB8*(1+$T$8) -> 8.5603226 | AD8: =AC8*(1+$T$8) -> 8.5537275 | AE8: =AD8*(1+$T$8) -> 8.5471375 | AF8: =AE8*(1+$T$8) -> 8.5405526 | ... AV8: =AU8*(1+$T$8) -> 8.4358811 | AX8: =AVERAGE(AF8:AT8) -> 8.494647
C11: D&A | D11: ='P&L Adjusted Pro Forma'!D40-'P&L Adjusted Pro Forma'!D28 -> 79 | E11: ='P&L Adjusted Pro Forma'!E40-'P&L Adjusted Pro Forma'!E28 -> 84.3 | F11: ='P&L Adjusted Pro Forma'!F40-'P&L Adjusted Pro Forma'!F28 -> 94.4 | G11: ='P&L Adjusted Pro Forma'!G40-'P&L Adjusted Pro Forma'!G28 -> 119 | H11: ='P&L Adjusted Pro Forma'!H40-'P&L Adjusted Pro Forma'!H28 -> 106 | I11: ='P&L Adjusted Pro Forma'!I40-'P&L Adjusted Pro Forma'!I28 -> 120.5 | J11: ='P&L Adjusted Pro Forma'!J40-'P&L Adjusted Pro Forma'!J28 -> 124.5 | K11: ='P&L Adjusted Pro Forma'!K40-'P&L Adjusted Pro Forma'!K28 -> 125.6 | ... R11: ='P&L Adjusted Pro Forma'!R40-'P&L Adjusted Pro Forma'!R28 -> 156.7 | T11: =((R11/D11)^(1/15))-1 -> 0.04671744 | X11: =R11+V12 -> 162.25 | Y11: =X11+$V$12 -> 167.8 | Z11: =Y11+$V$12 -> 173.35 | AA11: =Z11+$V$12 -> 178.9 | AB11: =AA11+$V$12 -> 184.45 | AC11: =AB11+$V$12 -> 190 | AD11: =AC11+$V$12 -> 195.55 | AE11: =AD11+$V$12 -> 201.1 | AF11: =AE11+$V$12 -> 206.65 | ... AV11: =AU11+$V$12 -> 295.45
C12: Δ D&A | E12: =E11-D11 -> 5.3 | F12: =F11-E11 -> 10.1 | G12: =G11-F11 -> 24.6 | H12: =H11-G11 -> -13 | I12: =I11-H11 -> 14.5 | J12: =J11-I11 -> 4 | K12: =K11-J11 -> 1.1 | L12: =L11-K11 -> 0.4 | ... R12: =R11-Q11 -> 3.7888791 | T12: =((R12/E12)^(1/15))-1 -> -0.022127293 | V12: =AVERAGE(E12:R12) -> 5.55
C14: CAPEX | D14: 2026 | E14: 2027 | F14: 2028 | G14: 2029 | H14: 2030 | I14: 2031
D15: =SUM(Y5:AB5) -> 487.94106 | E15: =SUM(Z5:AC5) -> 503.84966 | F15: =SUM(AA5:AD5) -> 520.36695 | G15: =SUM(AB5:AE5) -> 537.51789 | H15: =SUM(AC5:AF5) -> 555.32857 | I15: =SUM(AD5:AG5) -> 573.82615
C19: D&A | D19: 2025 | E19: 2026 | F19: 2027 | G19: 2028 | H19: 2029 | I19: 2030 | J19: 2031
D20: =X11+R11+Q11+P11 -> 623.56112 | E20: =SUM(Y11:AB11) -> 704.5 | F20: =SUM(Z11:AC11) -> 726.7 | G20: =SUM(AA11:AD11) -> 748.9 | H20: =SUM(AB11:AE11) -> 771.1 | I20: =SUM(AC11:AF11) -> 793.3 | J20: =SUM(AD11:AG11) -> 815.5
C21: Δ D&A | E21: =E20-D20 -> 80.938879 | F21: =F20-E20 -> 22.2 | G21: =G20-F20 -> 22.2 | H21: =H20-G20 -> 22.2 | I21: =I20-H20 -> 22.2 | J21: =J20-I20 -> 22.2

Sheet Balance Sheet
C2: Balance Sheet
B4: Português | C4: English | D4: 1Q22 | E4: 2Q22 | F4: 3Q22 | G4: 4Q22 | H4: 1Q23 | I4: 2Q23 | J4: 3Q23 | K4: 4Q23 | L4: 1Q24 | M4: 2Q24 | N4: 3Q24 | O4: 4Q24 | P4: 1Q25 | Q4: 2Q25 | R4: 3Q25 | S4: 4Q25 | T4: 1Q26 | U4: 2Q26 | V4: 3Q26 | W4: 4Q26 | X4: 1Q27 | Y4: 2Q27 | Z4: 3Q27 | AA4: 4Q27 | AB4: 1Q28 | AC4: 2Q28 | AD4: 3Q28 | AE4: 4Q28 | AF4: 1Q29 | AG4: 2Q29 | AH4: 3Q25 | AI4: 4Q29 | AJ4: 1Q30 | AK4: 2Q30 | AL4: 3Q30 | AM4: 4Q30 | AN4: 1Q31 | AO4: 2Q31 | AP4: 3Q31 | AQ4: 4Q31
B6: Ativo | C6: Assets
B7: Ativo circulante | C7: Current assets | D7: 2109.4 | E7: 2192.9 | F7: 2291.8 | G7: 2383.4 | H7: 2691 | I7: 2690.5 | J7: 2683.9 | K7: 2915.1 | L7: 2676.6 | M7: 2843.9 | N7: 6607.9 | O7: 6831.7 | P7: 7051.6 | Q7: 6866 | R7: 6874.5
B8: Caixa e equivalentes de caixa | C8: Cash and cash equivalents | D8: 106.7 | E8: 81.7 | F8: 74.9 | G8: 28.8 | H8: 83.6 | I8: 73.5 | J8: 60.7 | K8: 73.3 | L8: 53 | M8: 53.9 | N8: 162.4 | O8: 181.2 | P8: 136 | Q8: 177.4 | R8: 174.9
B9: Aplicações financeiras | C9: Financial Investments | D9: 603.6 | E9: 633.6 | F9: 471.2 | G9: 447.6 | H9: 699.5 | I9: 608.6 | J9: 582.9 | K9: 676.4 | L9: 539.8 | M9: 508.8 | N9: 604 | O9: 593.4 | P9: 967.4 | Q9: 645.8 | R9: 560.6
B10: Contas a receber | C10: Trade accounts receivables | D10: 631.3 | E10: 613.7 | F10: 722 | G10: 867.6 | H10: 743 | I10: 781.5 | J10: 921.8 | K10: 1125.4 | L10: 902.6 | M10: 963.3 | N10: 2512.5 | O10: 2816.3 | P10: 2448.8 | Q10: 2596.9 | R10: 2577
B11: Estoques | C11: Inventory | D11: 556.7 | E11: 651.7 | F11: 755.1 | G11: 772.1 | H11: 842.5 | I11: 864.5 | J11: 866.8 | K11: 774.3 | L11: 920.2 | M11: 968.2 | N11: 2313.1 | O11: 2218.8 | P11: 2457 | Q11: 2474.5 | R11: 2480.7
B12: Instrumentos financeiros - derivativos | C12: Financial Instruments - Derivatives | D12: 0.5 | E12: 0 | F12: 0 | G12: 0 | H12: 0 | I12: 0 | J12: 0 | K12: 0 | L12: 1 | M12: 52.9 | N12: 29.7 | O12: 136 | P12: 53.4 | Q12: 27.6 | R12: 18.7
B13: Impostos a recuperar | C13: Taxes recoverable | D13: 127.4 | E13: 148.2 | F13: 169 | G13: 187.5 | H13: 203.2 | I13: 231.7 | J13: 145 | K13: 111.7 | L13: 145.3 | M13: 131.4 | N13: 326.8 | O13: 323.4 | P13: 331.7 | Q13: 331.3 | R13: 381.6
B14: IRPJ e CSLL a recuperar | C14: Recovarable Income Tax and Social Contribution | D14: 2.6 | E14: 13.6 | F14: 14.4 | G14: 13.7 | H14: 19.3 | I14: 25.3 | J14: 5 | K14: 17.9 | L14: 19 | M14: 34.5 | N14: 224.8 | O14: 197.6 | P14: 225.4 | Q14: 239.8 | R14: 298.7
B15: Outros créditos | C15: Other credits | D15: 80.6 | E15: 50.4 | F15: 85.2 | G15: 66.1 | H15: 99.9 | I15: 105.4 | J15: 101.7 | K15: 136.1 | L15: 95.7 | M15: 130.9 | N15: 434.6 | O15: 365 | P15: 431.9 | Q15: 372.7 | R15: 382.3
B16: Ativo não circulante | C16: Non-current assets | D16: 1914.8 | E16: 2001.5 | F16: 2144.6 | G16: 2275.9 | H16: 2440.9 | I16: 2744.6 | J16: 2950.7 | K16: 3060.9 | L16: 3046.9 | M16: 3158.9 | N16: 8298.4 | O16: 8421.9 | P16: 8291.5 | Q16: 8650.8 | R16: 8641.8
B17: Aplicações financeiras | C17: Financial Investments | D17: 0 | E17: 0 | F17: 0 | G17: 0 | H17: 0 | I17: 0 | J17: 0 | K17: 0 | L17: 0 | M17: 0 | N17: 8.4 | O17: 1 | P17: 7.3 | Q17: 1.1 | R17: 7.8
B18: Instrumentos financeiros - derivativos | C18: Financial Instruments - Derivatives | D18: 0 | E18: 0 | F18: 0 | G18: 0 | H18: 0 | I18: 80.7 | J18: 77.5 | K18: 78.2 | L18: 48.8 | M18: 53.9 | N18: 59.2 | O18: 62.3 | P18: 68.9 | Q18: 65.9 | R18: 72.8
... B29: Total do Ativo | C29: Total assets | D29: 4024.2 | E29: 4194.4 | F29: 4436.4 | G29: 4659.3 | H29: 5131.9 | I29: 5435.1 | J29: 5634.6 | K29: 5975.9 | L29: 5723.5 | M29: 6002.8 | N29: 14906.3 | O29: 15253.5 | P29: 15343.1 | Q29: 15516.8 | R29: 15516.3
B31: Passivo | C31: Liabilities
B32: Passivo circulante | C32: Current liabilities | D32: 1269.3 | E32: 1433 | F32: 1501 | G32: 1635.4 | H32: 1589.6 | I32: 1703.2 | J32: 2173.3 | K32: 2292.3 | L32: 1872.1 | M32: 1986.1 | N32: 3706.2 | O32: 4517.1 | P32: 4562.1 | Q32: 4272.6 | R32: 3625.6
B33: Empréstimos e financiamentos | C33: Loans and financing | D33: 268.5 | E33: 345 | F33: 401.4 | G33: 392.3 | H33: 663 | I33: 642.5 | J33: 1087.4 | K33: 882.2 | L33: 747.5 | M33: 823 | N33: 903.2 | O33: 1476.5 | P33: 1904.1 | Q33: 1741.3 | R33: 1010.7
B34: Fornecedores | C34: Suppliers | D34: 588.7 | E34: 566 | F34: 637.5 | G34: 671.7 | H34: 571.5 | I34: 483.4 | J34: 569.1 | K34: 834.5 | L34: 647.5 | M34: 745 | N34: 1771.7 | O34: 1817.8 | P34: 1641.9 | Q34: 1524.3 | R34: 1552.1
B35: Instrumentos financeiros derivativos | C35: Financial Instruments - Derivatives | D35: 23.6 | E35: 13 | F35: 13.5 | G35: 1.8 | H35: 26.2 | I35: 72.2 | J35: 41.9 | K35: 59.5 | L35: 19.3 | M35: 0 | N35: 4.3 | O35: 0 | P35: 6.3 | Q35: 36.7 | R35: 9.1
B36: Arrendamento | C36: Lease | D36: 58.2 | E36: 62.1 | F36: 72.3 | G36: 89.6 | H36: 93.8 | I36: 97.5 | J36: 101.6 | K36: 107.7 | L36: 94.5 | M36: 96.8 | N36: 201.6 | O36: 213.1 | P36: 210.1 | Q36: 208.7 | R36: 226.2
B37: Imposto de renda e contribuição social a pagar | C37: Income tax and social contribution payable | D37: 38.1 | E37: 22 | F37: 12.7 | G37: 14.3 | H37: 8.5 | I37: 12.7 | J37: 29.1 | K37: 2.7 | L37: 10.3 | M37: 3.1 | N37: 0 | O37: 0 | P37: 0 | Q37: 0 | R37: 0
B38: Obrigações fiscais e sociais | C38: Fiscal and social obligations | D38: 49.3 | E38: 42.6 | F38: 31.2 | G38: 59.4 | H38: 38.2 | I38: 52.4 | J38: 59.2 | K38: 100.5 | L38: 84.1 | M38: 79.6 | N38: 205.9 | O38: 269.3 | P38: 207.3 | Q38: 231.2 | R38: 234.8
B39: Obrigações trabalhistas | C39: Employee-related obligations | D39: 68.3 | E39: 93.8 | F39: 123.8 | G39: 145.4 | H39: 75.9 | I39: 89.5 | J39: 100.8 | K39: 103.9 | L39: 85.8 | M39: 107 | N39: 361.6 | O39: 351.5 | P39: 364.6 | Q39: 331 | R39: 329.5
B40: Dividendos e juros sobre capital próprio | C40: Dividends and interest on equity | D40: 0 | E40: 111.6 | F40: 50 | G40: 72.2 | H40: 0 | I40: 82.8 | J40: 0 | K40: 0 | L40: 0 | M40: 0 | N40: 0 | O40: 0 | P40: 0 | Q40: 0 | R40: 0
B41: Parcelamento de impostos | C41: Tax installment | D41: 0 | E41: 0 | F41: 0 | G41: 0 | H41: 0 | I41: 0 | J41: 0 | K41: 1.9 | L41: 10.8 | M41: 9.3 | N41: 18.4 | O41: 17.6 | P41: 16.9 | Q41: 19.8 | R41: 14.2
B42: Obrigações a pagar na aquisição de controlada | C42: Payables from acquisition of subsidiary | D42: 100 | E42: 103.1 | F42: 83.2 | G42: 75.6 | H42: 32.6 | I42: 78.4 | J42: 78.8 | K42: 79.3 | L42: 48.1 | M42: 9.6 | N42: 30.6 | O42: 31.5 | P42: 0 | Q42: 0 | R42: 75
B43: Outras obrigações | C43: Other liabilities | D43: 74.6 | E43: 73.8 | F43: 75.4 | G43: 113.1 | H43: 79.9 | I43: 91.8 | J43: 105.4 | K43: 118.8 | L43: 122.9 | M43: 111.4 | N43: 207.6 | O43: 338.5 | P43: 209.6 | Q43: 178.3 | R43: 172.7
... B47: Arrendamento | C47: Lease | D47: 168.8 | E47: 180.1 | F47: 236.8 | G47: 284.9 | H47: 339.9 | I47: 395 | J47: 401.9 | K47: 407.5 | L47: 370.5 | M47: 368.7 | N47: 626.2 | O47: 662.5 | P47: 623.3 | Q47: 599.7 | R47: 564.9
B48: Partes relacionadas | C48: Related parties | D48: 0 | E48: - | F48: - | G48: - | H48: - | I48: - | J48: - | K48: - | L48: - | M48: - | N48: 0 | O48: 0 | P48: 0 | Q48: 0 | R48: 0
B49: Provisões para riscos trabalhistas, fiscais e cíveis | C49: Provisions for labor, tax, and civil risks | D49: 14.2 | E49: 14.4 | F49: 16.6 | G49: 17.8 | H49: 17.1 | I49: 19.2 | J49: 17.2 | K49: 16.1 | L49: 15.6 | M49: 17.5 | N49: 649.3 | O49: 675.5 | P49: 578.3 | Q49: 586.8 | R49: 584.8
B50: Outras obrigações | C50: Other liabilities | D50: 2.1 | E50: 2.2 | F50: 2.5 | G50: 2.5 | H50: 2.7 | I50: 2.8 | J50: 0 | K50: 0 | L50: 0 | M50: 0 | N50: 20.7 | O50: 25.6 | P50: 16 | Q50: 10 | R50: 9
B51: Impostos diferidos | C51: Deferred tax | D51: 2.9 | E51: 2.7 | F51: 3.5 | G51: 3.4 | H51: 1.7 | I51: 0.8 | J51: 1.3 | K51: 0 | L51: 0 | M51: 0 | N51: 239.9 | O51: 245.6 | P51: 226.4 | Q51: 222.7 | R51: 215
B52: Obrigações a pagar na aquisição de controlada | C52: Payables from acquisition of subsidiary | D52: 52 | E52: 58 | F52: 51 | G52: 51.1 | H52: 41.9 | I52: 42.2 | J52: 42.3 | K52: 42.4 | L52: 121.7 | M52: 120.5 | N52: 191.1 | O52: 196.1 | P52: 168.5 | Q52: 171.7 | R52: 94.1
B53: Parcelamento de impostos | C53: Tax installment | D53: 1 | E53: 1.2 | F53: - | G53: - | H53: - | I53: - | J53: 6.7 | K53: 6.3 | L53: 29.8 | M53: 28.7 | N53: 29.2 | O53: 27.6 | P53: 24.8 | Q53: 18.6 | R53: 20.5
B54: Instrumentos financeiros - derivativos | C54: Financial Instruments - Derivatives | D54: 0 | E54: 0 | F54: 0 | G54: 0 | H54: 0 | I54: 80.7 | J54: 77.5 | K54: 78.2 | L54: 0 | M54: 0 | N54: 0 | O54: 0 | P54: 0 | Q54: 0 | R54: 0
B55: Receitas diferidas | C55: Deferred revenue | D55: 0 | E55: - | F55: - | G55: - | H55: - | I55: - | J55: - | K55: 5.1 | L55: 5.1 | M55: 4.4 | N55: 4.1 | O55: 3.8 | P55: 3.5 | Q55: 3.1 | R55: 2.8
B56: Patrimônio líquido | C56: Shareholder's Equity | D56: 2498.3 | E56: 2492.5 | F56: 2614.9 | G56: 2654.6 | H56: 2741.9 | I56: 2805.7 | J56: 2909.3 | K56: 2929.1 | L56: 2957.5 | M56: 3087.4 | N56: 7883.8 | O56: 7721.5 | P56: 7804.4 | Q56: 8339.6 | R56: 8347.7
B57: Capital social | C57: Equity Capital | D57: 1645.5 | E57: 1645.5 | F57: 1671.7 | G57: 1671.7 | H57: 1671.7 | I57: 1738.2 | J57: 1738.2 | K57: 1738.2 | L57: 1738.2 | M57: 1738.2 | N57: 2317.2 | O57: 2317.2 | P57: 2317.2 | Q57: 2317.2 | R57: 2317.2
...

Sheet P&L Adjusted Pro Forma
C2: P&L Adjusted Pro Forma
B4: Português | C4: English | D4: 1Q22 | E4: 2Q22 | F4: 3Q22 | G4: 4Q22 | H4: 1Q23 | I4: 2Q23 | J4: 3Q23 | K4: 4Q23 | L4: 1Q24 | M4: 2Q24 | N4: 3Q24 | O4: 4Q24 | P4: 1Q25 | Q4: 2Q25 | R4: 3Q25 | S4: 4Q25 | T4: 1Q26 | U4: 2Q26 | V4: 3Q26 | W4: 4Q26 | X4: 1Q27 | Y4: 2Q27 | Z4: 3Q27 | AA4: 4Q27 | AB4: 1Q28 | AC4: 2Q28 | AD4: 3Q28 | AE4: 4Q28 | AF4: 1Q29 | AG4: 2Q29 | AH4: 3Q25 | AI4: 4Q29 | AJ4: 1Q30 | AK4: 2Q30 | AL4: 3Q30 | AM4: 4Q30 | AN4: 1Q31 | AO4: 2Q31 | AP4: 3Q31 | AQ4: 4Q31
B5: Receita Bruta | C5: Gross Revenue | D5: 2271.3 | E5: 2613.5 | F5: 2969.5 | G5: 3306.3 | H5: 2789.9 | I5: 3047.9 | J5: 3274.3 | K5: 3667.3 | L5: 2894.1 | M5: 3370.5 | N5: 3673.5 | O5: 4221.7 | P5: 3311.8 | Q5: 3620 | R5: 3716.2 | S5: ='Revenue per BU and channel'!V73 -> 3856.3271 | T5: ='Revenue per BU and channel'!W73 -> 1995.9347 | U5: ='Revenue per BU and channel'!X73 -> 2098.903 | V5: ='Revenue per BU and channel'!Y73 -> 2207.9466 | W5: ='Revenue per BU and channel'!Z73 -> 2323.2968 | X5: ='Revenue per BU and channel'!AA73 -> 2445.1531 | Y5: ='Revenue per BU and channel'!AB73 -> 2573.6682 | Z5: ='Revenue per BU and channel'!AC73 -> 2708.931 | ... AQ5: ='Revenue per BU and channel'!AT73 -> 4782.9085
B6: Deduções | C6: Deductions | D6: -354.6 | E6: -402.7 | F6: -466.4 | G6: -557 | H6: -492 | I6: -551.2 | J6: -559.6 | K6: -666 | L6: -527 | M6: -601.2 | N6: -635.3 | O6: -817.8 | P6: -615.3 | Q6: -718.6 | R6: -746.4 | S6: =S7*(-S5) -> -683.26756 | T6: =T7*(-T5) -> -353.64153 | U6: =U7*(-U5) -> -371.88556 | V6: =V7*(-V5) -> -391.20599 | W6: =W7*(-W5) -> -411.64385 | X6: =X7*(-X5) -> -433.23445 | Y6: =Y7*(-Y5) -> -456.00488 | Z6: =Z7*(-Z5) -> -479.97086 | ... AQ6: =AQ7*(-AQ5) -> -847.4401
B7: as % of gross revenue | D7: =-D6/D5 -> 0.15612204 | E7: =-E6/E5 -> 0.15408456 | F7: =-F6/F5 -> 0.15706348 | G7: =-G6/G5 -> 0.16846626 | H7: =-H6/H5 -> 0.17635041 | I7: =-I6/I5 -> 0.18084583 | J7: =-J6/J5 -> 0.17090676 | K7: =-K6/K5 -> 0.181605 | ... R7: =-R6/R5 -> 0.20085033 | S7: =AVERAGE(D7:R7) -> 0.17718091 | T7: =S7 -> 0.17718091 | U7: =T7 -> 0.17718091 | V7: =U7 -> 0.17718091 | W7: =V7 -> 0.17718091 | X7: =W7 -> 0.17718091 | Y7: =X7 -> 0.17718091 | Z7: =Y7 -> 0.17718091 | AA7: =Z7 -> 0.17718091 | ... AQ7: =AP7 -> 0.17718091
B9: Receita Líquida | C9: Net Revenue | D9: 1916.7 | E9: 2210.8 | F9: 2503.1 | G9: 2749.3 | H9: 2297.9 | I9: 2496.7 | J9: 2714.7 | K9: 3001.3 | L9: 2367.1 | M9: 2769.3 | N9: 3038.2 | O9: 3403.9 | P9: 2696.5 | Q9: 2901.4 | R9: 2969.8 | S9: =S5+S6 -> 3173.0596 | T9: =T5+T6 -> 1642.2931 | U9: =U5+U6 -> 1727.0175 | V9: =V5+V6 -> 1816.7406 | W9: =W5+W6 -> 1911.653 | X9: =X5+X6 -> 2011.9186 | Y9: =Y5+Y6 -> 2117.6633 | Z9: =Z5+Z6 -> 2228.9601 | ... AQ9: =AQ5+AQ6 -> 3935.4684
B10: Custo da Mercadoria Vendida (CMV) | C10: Cost of Goods Sold (COGS) | D10: -889.6 | E10: -951.9 | F10: -1132.9 | G10: -1282.8 | H10: -1057.9 | I10: -1105.6 | J10: -1226.7 | K10: -1318.1 | L10: -1077.6 | M10: -1214.5 | N10: -1386.7 | O10: -1515.8 | P10: -1219.7 | Q10: -1280.9 | R10: -1345.9 | S10: =-S11*S5 -> -1428.1011 | T10: =-T11*T5 -> -739.14801 | U10: =-U11*U5 -> -777.27995 | V10: =-V11*V5 -> -817.6617 | W10: =-W11*W5 -> -860.37898 | X10: =-X11*X5 -> -905.5056 | Y10: =-Y11*Y5 -> -953.0982 | Z10: =-Z11*Z5 -> -1003.1896 | ... AQ10: =-AQ11*AQ5 -> -1771.239
B11: as % of gross revenue | D11: =-D10/D5 -> 0.39166997 | E11: =-E10/E5 -> 0.36422422 | F11: =-F10/F5 -> 0.38151204 | G11: =-G10/G5 -> 0.38798657 | H11: =-H10/H5 -> 0.37918922 | I11: =-I10/I5 -> 0.36274156 | J11: =-J10/J5 -> 0.37464496 | K11: =-K10/K5 -> 0.35941974 | ... R11: =-R10/R5 -> 0.36217103 | S11: =AVERAGE(D11:R11) -> 0.37032676 | T11: =S11 -> 0.37032676 | U11: =T11 -> 0.37032676 | V11: =U11 -> 0.37032676 | W11: =V11 -> 0.37032676 | X11: =W11 -> 0.37032676 | Y11: =X11 -> 0.37032676 | Z11: =Y11 -> 0.37032676 | AA11: =Z11 -> 0.37032676 | ... AQ11: =AP11 -> 0.37032676
B13: CMV (ex. D&A) | C13: COGS (ex. D&A) | D13: -881.1 | E13: -943.2 | F13: -1123.9 | G13: -1273.4 | H13: -1048.9 | I13: -1096.5 | J13: -1217.7 | K13: -1309.1 | L13: -1068 | M13: -1204.8 | N13: -1376.5 | O13: -1504.5 | P13: -1209.2 | Q13: -1271.2 | R13: -1335.5
B14: CMV (ex. D&A ex. IFRS-16) | C14: COGS (ex. D&A ex. IFRS-16) | D14: -882.3 | E14: -944.4 | F14: -1125.1 | G14: -1274.5 | H14: -1050 | I14: -1097.6 | J14: -1218.9 | K14: -1310 | L14: -1069.3 | M14: -1206.1 | N14: -1377.8 | O14: -1505.8 | P14: -1210.5 | Q14: -1272.5 | R14: -1336.8
B15: Arrendamentos (Impacto IFRS-16) | C15: Leases (IFRS-16 Impact) | D15: 1.2 | E15: 1.2 | F15: 1.2 | G15: 1.1 | H15: 1.1 | I15: 1.1 | J15: 1.2 | K15: 0.9 | L15: 1.3 | M15: 1.3 | N15: 1.3 | O15: 1.3 | P15: 1.3 | Q15: 1.3 | R15: 1.3
B16: Depreciação & Amortização | C16: Depreciation and Amortization | D16: -8.5 | E16: -8.7 | F16: -9 | G16: -9.4 | H16: -9 | I16: -9.1 | J16: -9 | K16: -9 | L16: -9.6 | M16: -9.7 | N16: -10.2 | O16: -11.3 | P16: -10.5 | Q16: -9.7 | R16: -10.4
B17: Lucro Bruto | C17: Gross Profit | D17: 1027.1 | E17: 1258.9 | F17: 1370.2 | G17: 1466.5 | H17: 1240 | I17: 1391.1 | J17: 1488 | K17: 1683.2 | L17: 1289.5 | M17: 1554.8 | N17: 1651.5 | O17: 1888.1 | P17: 1476.8 | Q17: 1620.5 | R17: 1623.9 | S17: =S9+S10 -> 1744.9585 | T17: =T9+T10 -> 903.14513 | U17: =U9+U10 -> 949.73753 | V17: =V9+V10 -> 999.07889 | W17: =W9+W10 -> 1051.274 | X17: =X9+X10 -> 1106.413 | Y17: =Y9+Y10 -> 1164.5651 | Z17: =Z9+Z10 -> 1225.7705 | ... AQ17: =AQ9+AQ10 -> 2164.2294
B18: Despesa Total | C18: Total Expenses | D18: -844.2 | E18: -940.9 | F18: -1045 | G18: -1148.8 | H18: -1009 | I18: -1056.5 | J18: -1154.7 | K18: -1310.1 | L18: -1068.5 | M18: -1197.3 | N18: -1320.5 | O18: -1525.4 | P18: -1200.8 | Q18: -1237.8 | R18: -1303.9 | S18: =S19*-S5 -> -1375.3866 | T18: =T19*-T5 -> -711.86436 | U18: =U19*-U5 -> -748.58877 | V18: =V19*-V5 -> -787.47992 | W18: =W19*-W5 -> -828.62041 | X18: =X19*-X5 -> -872.08131 | Y18: =Y19*-Y5 -> -917.91716 | Z18: =Z19*-Z5 -> -966.15958 | ... AQ18: =AQ19*-AQ5 -> -1705.8585
B19: as % of gross revenue | D19: =-D18/D5 -> 0.37168142 | E19: =-E18/E5 -> 0.36001531 | F19: =-F18/F5 -> 0.3519111 | G19: =-G18/G5 -> 0.34745788 | H19: =-H18/H5 -> 0.36166171 | I19: =-I18/I5 -> 0.34663211 | J19: =-J18/J5 -> 0.35265553 | K19: =-K18/K5 -> 0.3572383 | ... R19: =-R18/R5 -> 0.35086917 | S19: =AVERAGE(D19:R19) -> 0.35665715 | T19: =S19 -> 0.35665715 | U19: =T19 -> 0.35665715 | V19: =U19 -> 0.35665715 | W19: =V19 -> 0.35665715 | X19: =W19 -> 0.35665715 | Y19: =X19 -> 0.35665715 | Z19: =Y19 -> 0.35665715 | AA19: =Z19 -> 0.35665715 | ... AQ19: =AP19 -> 0.35665715
B21: Despesas | C21: Expenses | D21: -773.7 | E21: -865.3 | F21: -959.6 | G21: -1039.2 | H21: -912 | I21: -945.1 | J21: -1039.2 | K21: -1193.5 | L21: -952.1 | M21: -1073 | N21: -1184.8 | O21: -1380.2 | P21: -1059.6 | Q21: -1094.6 | R21: -1157.6
B22: Fixas | C22: Fixed | D22: -344.4 | E22: -377.4 | F22: -408.9 | G22: -436 | H22: -390.6 | I22: -374.2 | J22: -439.2 | K22: -470.3 | L22: -435.7 | M22: -448 | N22: -473.1 | O22: -536.5 | P22: -474.9 | Q22: -453.4 | R22: -464.7
B23: Variáveis | C23: Variable | D23: -377.1 | E23: -406.2 | F23: -456.6 | G23: -556.2 | H23: -452.7 | I23: -473 | J23: -523.2 | K23: -618.8 | L23: -467.8 | M23: -533.8 | N23: -588.5 | O23: -719.6 | P23: -535 | Q23: -569.4 | R23: -590.1
B24: Eventuais | C24: Eventuals | D24: -93.9 | E24: -126.6 | F24: -142.3 | G24: -129.2 | H24: -124.3 | I24: -157.4 | J24: -137.8 | K24: -176.8 | L24: -114.2 | M24: -154 | N24: -189.4 | O24: -199.4 | P24: -117.1 | Q24: -144.7 | R24: -172.2
B25: Arrendamentos (Impacto IFRS-16) | C25: Leases (IFRS-16 Impact) | D25: 41.7 | E25: 44.9 | F25: 48.2 | G25: 82.2 | H25: 55.6 | I25: 59.5 | J25: 61 | K25: 72.4 | L25: 65.6 | M25: 62.8 | N25: 66.2 | O25: 75.3 | P25: 67.4 | Q25: 72.9 | R25: 69.4
B26: Depreciação e Amortização | C26: Depreciation and Amortization | D26: -70.5 | E26: -75.6 | F26: -85.4 | G26: -109.6 | H26: -97 | I26: -111.4 | J26: -115.5 | K26: -116.6 | L26: -116.4 | M26: -124.3 | N26: -135.7 | O26: -145.2 | P26: -141.2 | Q26: -143.2 | R26: -146.3
B27: Perda por Impairment | C27: Impairment losses | D27: 0 | E27: 0 | F27: 0 | G27: 0 | H27: 0 | I27: 0 | J27: 0 | K27: 0 | L27: 0 | M27: 0 | N27: 0 | O27: 0 | P27: 0 | Q27: 0 | R27: 0
B28: EBIT | C28: EBIT | D28: 182.9 | E28: 318 | F28: 325.2 | G28: 317.7 | H28: 231 | I28: 334.6 | J28: 333.3 | K28: 373.1 | L28: 221 | M28: 357.5 | N28: 331 | O28: 362.7 | P28: 276 | Q28: 382.7 | R28: 320 | S28: =S17+S18 -> 369.57183 | T28: =T17+T18 -> 191.28077 | U28: =U17+U18 -> 201.14876 | V28: =V17+V18 -> 211.59897 | W28: =W17+W18 -> 222.65358 | X28: =X17+X18 -> 234.3317 | Y28: =Y17+Y18 -> 246.64797 | Z28: =Z17+Z18 -> 259.6109 | ... AQ28: =AQ17+AQ18 -> 458.37093
B29: Resultado Financeiro | C29: Financial Results | D29: -63.2 | E29: -70.3 | F29: -91.2 | G29: -128.1 | H29: -116.3 | I29: -146 | J29: -124.4 | K29: -144.7 | L29: -143.8 | M29: -151.8 | N29: -159.4 | O29: -156.8 | P29: -157.7 | Q29: -199.5 | R29: -208.7 | S29: =S30*-S5 -> -160.77397 | T29: =T30*-T5 -> -83.212427 | U29: =U30*-U5 -> -87.505277 | V29: =V30*-V5 -> -92.051407 | W29: =W30*-W5 -> -96.860469 | X29: =X30*-X5 -> -101.94077 | Y29: =Y30*-Y5 -> -107.29869 | Z29: =Z30*-Z5 -> -112.93793 | ... AQ29: =AQ30*-AQ5 -> -199.40404
B30: as % of gross revenue | D30: =-D29/D5 -> 0.027825474 | E30: =-E29/E5 -> 0.026898795 | F30: =-F29/F5 -> 0.030712241 | G30: =-G29/G5 -> 0.038744216 | H30: =-H29/H5 -> 0.041686082 | I30: =-I29/I5 -> 0.047901834 | J30: =-J29/J5 -> 0.037992853 | K30: =-K29/K5 -> 0.039456821 | ... R30: =-R29/R5 -> 0.056159518 | S30: =AVERAGE(D30:R30) -> 0.041690957 | T30: =S30 -> 0.041690957 | U30: =T30 -> 0.041690957 | V30: =U30 -> 0.041690957 | W30: =V30 -> 0.041690957 | X30: =W30 -> 0.041690957 | Y30: =X30 -> 0.041690957 | Z30: =Y30 -> 0.041690957 | AA30: =Z30 -> 0.041690957 | ... AQ30: =AP30 -> 0.041690957
B32: EBT | C32: EBT | D32: 119.7 | E32: 247.7 | F32: 234 | G32: 189.6 | H32: 114.7 | I32: 188.6 | J32: 208.9 | K32: 228.4 | L32: 77.2 | M32: 205.7 | N32: 171.6 | O32: 205.9 | P32: 118.3 | Q32: 183.2 | R32: 111.3 | S32: =S28+S29 -> 208.79786 | T32: =T28+T29 -> 108.06834 | U32: =U28+U29 -> 113.64348 | V32: =V28+V29 -> 119.54756 | W32: =W28+W29 -> 125.79311 | X32: =X28+X29 -> 132.39092 | Y32: =Y28+Y29 -> 139.34928 | Z32: =Z28+Z29 -> 146.67298 | ... AQ32: =AQ28+AQ29 -> 258.96689
B33: IRPJ e CSLL | C33: Income Tax and Social Contribution | D33: 8.2 | E33: 22.2 | F33: -3.7 | G33: 30.8 | H33: 39.2 | I33: 48.7 | J33: 20.7 | K33: 34.5 | L33: 24.6 | M33: -49.6 | N33: -7.7 | O33: -37 | P33: -0.6 | Q33: 100.5 | R33: 90 | S33: =-S34*S32 -> -70.991271 | T33: =-T34*T32 -> -36.743236 | U33: =-U34*U32 -> -38.638785 | V33: =-V34*V32 -> -40.646171 | W33: =-W34*W32 -> -42.769658 | X33: =-X34*X32 -> -45.012914 | Y33: =-Y34*Y32 -> -47.378755 | Z33: =-Z34*Z32 -> -49.868812 | ... AQ33: =-AQ34*AQ32 -> -88.048742
B34: as % of gross revenue | S34: 0.34 | T34: =S34 -> 0.34 | U34: =T34 -> 0.34 | V34: =U34 -> 0.34 | W34: =V34 -> 0.34 | X34: =W34 -> 0.34 | Y34: =X34 -> 0.34 | Z34: =Y34 -> 0.34 | AA34: =Z34 -> 0.34 | ... AQ34: =AP34 -> 0.34
B36: Lucro (Prejuízo) | C36: Profit (Loss) | D36: 127.9 | E36: 269.9 | F36: 230.3 | G36: 220.4 | H36: 153.9 | I36: 237.3 | J36: 229.6 | K36: 262.9 | L36: 101.8 | M36: 156.1 | N36: 163.9 | O36: 168.9 | P36: 117.7 | Q36: 283.7 | R36: 201.3 | S36: =S32+S33 -> 137.80658 | T36: =T32+T33 -> 71.325105 | U36: =U32+U33 -> 75.0047 | V36: =V32+V33 -> 78.901391 | W36: =W32+W33 -> 83.023454 | X36: =X32+X33 -> 87.37801 | Y36: =Y32+Y33 -> 91.970524 | Z36: =Z32+Z33 -> 96.804164 | ... AQ36: =AQ32+AQ33 -> 170.91815
B38: Lucro Bruto | C38: Gross Profit | D38: 1027.1 | E38: 1258.9 | F38: 1370.2 | G38: 1466.5 | H38: 1240 | I38: 1391.1 | J38: 1488 | K38: 1683.2 | L38: 1289.5 | M38: 1554.8 | N38: 1651.5 | O38: 1888.1 | P38: 1476.8 | Q38: 1620.5111 | R38: 1623.9
B39: Margem Bruta | C39: Gross Margin | D39: 0.536 | E39: 0.569 | F39: 0.547 | G39: 0.533 | H39: 0.54 | I39: 0.557 | J39: 0.548 | K39: 0.561 | L39: 0.545 | M39: 0.561 | N39: 0.544 | O39: 0.555 | P39: 0.548 | Q39: 0.559 | R39: 0.547
B40: EBITDA | C40: EBITDA | D40: 261.9 | E40: 402.3 | F40: 419.6 | G40: 436.7 | H40: 337 | I40: 455.1 | J40: 457.8 | K40: 498.7 | L40: 347 | M40: 491.5 | N40: 476.9 | O40: 519.2 | P40: 427.7 | Q40: 535.61112 | R40: 476.7
B41: Margem EBITDA | C41: EBITDA Margin | D41: 0.137 | E41: 0.182 | F41: 0.168 | G41: 0.159 | H41: 0.147 | I41: 0.182 | J41: 0.169 | K41: 0.166 | L41: 0.147 | M41: 0.177 | N41: 0.157 | O41: 0.153 | P41: 0.159 | Q41: 0.185 | R41: 0.161
B42: EBITDA (pré IFRS-16) | C42: EBITDA (ex. IFRS-16) | D42: 219 | E42: 356.2 | F42: 370.2 | G42: 353.4 | H42: 280.3 | I42: 394.5 | J42: 395.6 | K42: 425.4 | L42: 280.1 | M42: 427.4 | N42: 409.4 | O42: 442.6 | P42: 359 | Q42: 461.41112 | R42: 406
B43: Margem EBITDA (pré IFRS-16) | C43: EBITDA Margin (ex. IFRS-16) | D43: 0.114 | E43: 0.161 | F43: 0.148 | G43: 0.129 | H43: 0.122 | I43: 0.158 | J43: 0.146 | K43: 0.142 | L43: 0.118 | M43: 0.154 | N43: 0.135 | O43: 0.13 | P43: 0.133 | Q43: 0.159 | R43: 0.137
B44: Lucro Líquido | C44: Net Income | D44: 127.9 | E44: 269.9 | F44: 230.3 | G44: 220.4 | H44: 153.9 | I44: 237.3 | J44: 229.6 | K44: 262.9 | L44: 101.8 | M44: 156.1 | N44: 163.9 | O44: 168.9 | P44: 117.7 | Q44: 283.71112 | R44: 201.3
B45: Margem Líquida | C45: Net Margin | D45: 0.067 | E45: 0.122 | F45: 0.092 | G45: 0.08 | H45: 0.067 | I45: 0.095 | J45: 0.085 | K45: 0.088 | L45: 0.043 | M45: 0.056 | N45: 0.054 | O45: 0.05 | P45: 0.044 | Q45: 0.098 | R45: 0.068 | S45: =S36/S5 -> 0.03573519 | T45: =T36/T5 -> 0.03573519 | U45: =U36/U5 -> 0.03573519 | V45: =V36/V5 -> 0.03573519 | W45: =W36/W5 -> 0.03573519 | X45: =X36/X5 -> 0.03573519 | Y45: =Y36/Y5 -> 0.03573519 | Z45: =Z36/Z5 -> 0.03573519 | ... AQ45: =AQ36/AQ5 -> 0.03573519
D49: 2025 | E49: 2026 | F49: 2027 | G49: 2028 | H49: 2029 | I49: 2030 | J49: 2031
C52: EBIT | E52: =SUM(T28:W28) -> 826.68208 | F52: =SUM(U28:X28) -> 869.73301 | G52: =SUM(V28:Y28) -> 915.23222 | H52: =SUM(W28:Z28) -> 963.24415 | I52: =SUM(X28:AA28) -> 1013.8112 | J52: =SUM(Y28:AB28) -> 1066.9459
C54: Net Revenue | D54: =SUM(P9:S9) -> 11740.76 | E54: =SUM(Q9:T9) -> 10686.553 | F54: =SUM(R9:U9) -> 9512.1702 | G54: =SUM(S9:V9) -> 8359.1108 | H54: =SUM(T9:W9) -> 7097.7042 | I54: =SUM(U9:X9) -> 7467.3296 | J54: =SUM(V9:Y9) -> 7857.9755
...

Sheet VALUATION
E9: Free Cash Flow to Firm | J9: 2026 | K9: 2027 | L9: 2028 | M9: 2029 | N9: 2030 | O9: 2031
E11: EBIT | J11: =SUM('P&L Adjusted Pro Forma'!T28:W28) -> 826.68208 | K11: =SUM('P&L Adjusted Pro Forma'!U28:X28) -> 869.73301 | L11: =SUM('P&L Adjusted Pro Forma'!V28:Y28) -> 915.23222 | M11: =SUM('P&L Adjusted Pro Forma'!W28:Z28) -> 963.24415 | N11: =SUM('P&L Adjusted Pro Forma'!X28:AA28) -> 1013.8112 | O11: =SUM('P&L Adjusted Pro Forma'!Y28:AB28) -> 1066.9459
E12: Tax Shield | J12: =(1-0.34) -> 0.66 | K12: =J12 -> 0.66 | L12: =K12 -> 0.66 | M12: =L12 -> 0.66 | N12: =M12 -> 0.66 | O12: =N12 -> 0.66
E13: (=) NOPAT | J13: =J11*J12 -> 545.61017 | K13: =K11*K12 -> 574.02379 | L13: =L11*L12 -> 604.05326 | M13: =M11*M12 -> 635.74114 | N13: =N11*N12 -> 669.11541 | O13: =O11*O12 -> 704.18429
E14: (+) D&A | J14: =CAPEX!D20 -> 623.56112 | K14: =CAPEX!E20 -> 704.5 | L14: =CAPEX!F20 -> 726.7 | M14: =CAPEX!G20 -> 748.9 | N14: =CAPEX!H20 -> 771.1 | O14: =CAPEX!I20 -> 793.3
E15: (-) CAPEX | J15: =-CAPEX!D15 -> -487.94106 | K15: =-CAPEX!E15 -> -503.84966 | L15: =-CAPEX!F15 -> -520.36695 | M15: =-CAPEX!G15 -> -537.51789 | N15: =-CAPEX!H15 -> -555.32857 | O15: =-CAPEX!I15 -> -573.82615
E16: (-) Change in Working Capital | J16: =-'Balance Sheet'!F147 -> -2229.0732 | K16: =-'Balance Sheet'!G147 -> 767.2139 | L16: =-'Balance Sheet'!H147 -> 903.26867 | M16: =-'Balance Sheet'!I147 -> 1015.8607 | N16: =-'Balance Sheet'!J147 -> 850.54686 | O16: =-'Balance Sheet'!K147 -> 39.460912
E18: (=) FCFF | J18: =SUM(J13:J16) -> -1547.843 | K18: =SUM(K13:K16) -> 1541.888 | L18: =SUM(L13:L16) -> 1713.655 | M18: =SUM(M13:M16) -> 1862.984 | N18: =SUM(N13:N16) -> 1735.4337 | O18: =SUM(O13:O16) -> 963.11906
E20: Fluxo de Caixa para a Firma a ser Descontado | J20: =J18 -> -1547.843 | K20: =K18 -> 1541.888 | L20: =L18 -> 1713.655 | M20: =M18 -> 1862.984 | N20: =N18 -> 1735.4337 | O20: =O18 -> 963.11906
E21: Valor Terminal | O21: =(O20*(1+G69))/(O24-G69) -> 8545.3593
O22: =P22*'P&L Adjusted Pro Forma'!J55 -> 9412.2295 | P22: 5 | Q22: EBITDA @31
E24: % WACC (R$, nominal) | J24: =$G$67 -> 0.12383374 | K24: =J24 -> 0.12383374 | L24: =K24 -> 0.12383374 | M24: =L24 -> 0.12383374 | N24: =M24 -> 0.12383374 | O24: =N24 -> 0.12383374
E26: Períodos a serem Descontados (Fluxo de Caixa) | I26: 0 | J26: 1 | K26: 2 | L26: 3 | M26: 4 | N26: 5 | O26: 6
E27: Períodos a serem Descontados (Valor Terminal) | O27: 6
E29: VPL dos Fluxos de Caixa para a Firma @2025E, EoP | I29: =SUM(J29:Q29) -> 3664.8095 | J29: =J20*(1/(1+J24)^J26) -> -1377.2882 | K29: =K20*(1/(1+K24)^K26) -> 1220.8117 | L29: =L20*(1/(1+L24)^L26) -> 1207.3055 | M29: =M20*(1/(1+M24)^M26) -> 1167.8871 | N29: =N20*(1/(1+N24)^N26) -> 968.04977 | O29: =O20*(1/(1+O24)^O26) -> 478.04367
E30: VPL do Valor Terminal @2025E, EoP | I30: =O21/(1+O24)^O27 -> 4241.4849
E31: Valor Terminal enquanto % do Valor da Firma | I31: =I30/I34 -> 0.53646938
E34: Valor da Firma | I34: =I29+I30 -> 7906.2944
E35: (-) Dívida Líquida 2025A | I35: =-('Balance Sheet'!R46+'Balance Sheet'!R33) -> -3062.6
E36: (=) Valor do Equity | I36: =I34+I35 -> 4843.6944
E38: EV/EBITDA | G38: x | I38: =I34/'P&L Adjusted Pro Forma'!D55 -> 4.0096167
E39: EV/Receita Líquida | G39: x | I39: =I34/'P&L Adjusted Pro Forma'!D54 -> 0.6734057
E41: Total de ON | I41: 206489813
E42: Price por Share | I42: =(I34*1000000)/I41 -> 38.289029
E44: P/L | I44: =I42/I45 -> 10.676872
E45: Lucro por Ação | I45: {=SUM(('P&L Adjusted Pro Forma'!P36:S36)*1000000)/VALUATION!I41} -> 3.5861652
E47: Preço em 29.01.26 | I47: 27
E48: Upside Prospectivo | I48: =I42/I47-1 -> 0.41811218
Y51: Pag 93: | Z51: https://api.mziq.com/mzfilemanager/v2/d/2edfd667-eaa1-4187-9777-1528284720de/e89d181a-523a-363f-3154-bc922be24581?origin=2
E53: Cost of Capital
E54: WACC Build-Up
E56: Risk-free rate Brazil | G56: 0.1374
E57: NTNB 2029 Spread (Jan/26) | G57: 0.0683
E58: Long-Term Inflation | G58: 0.0585
E59: Beta (β) | G59: =G78 -> 0.27
E60: Risk Premium Brazil (Damodaran, 2025) | G60: 0.0721
E61: Cost of Equity (Ke) via CAPM | G61: =G56+G60*G59 -> 0.156867
E62: Cost of Debt (Kd) | G62: =(14.9+1.17)/100 -> 0.1607
E63: Capital Structure | G63: -
E64: Debt-to-Value | G64: =1-G65 -> 0.65019695
...

Sheet Preço Alvo
J9: Casa de Research | M9: Preço Alvo por ON
J11: BTG | M11: 51
J12: XP | M12: 55
J13: Itaú BBA | M13: 36
J14: UBS | M14: 37
J15: CITI | M15: 28
J16: Empiricus | M16: 41
J20: Média | M20: =AVERAGE(M11:M16) -> 41.333333

Sheet Stores
C2: Stores
B4: Português | C4: English | D4: 1Q22 | E4: 2Q22 | F4: 3Q22 | G4: 4Q22 | H4: 1Q23 | I4: 2Q23 | J4: 3Q23 | K4: 4Q23 | L4: 1Q24 | M4: 2Q24 | N4: 3Q24 | O4: 4Q24 | P4: 1Q25 | Q4: 2Q25 | R4: 3Q25 | U4: CQGR | W4: 4Q25 | X4: 1Q26 | Y4: 2Q26 | Z4: 3Q26 | AA4: 4Q26 | AB4: 1Q27 | AC4: 2Q27 | AD4: 3Q27 | AE4: 4Q27 | AF4: 1Q28 | AG4: 2Q28 | AH4: 3Q28 | AI4: 4Q28 | AJ4: 1Q29 | AK4: 2Q29 | AL4: 3Q25 | AM4: 4Q29 | AN4: 1Q30 | AO4: 2Q30 | AP4: 3Q30 | AQ4: 4Q30 | AR4: 1Q31 | AS4: 2Q31 | AT4: 3Q31 | AU4: 4Q31
B6: Azzas 2154 (Consolidado) | C6: Azzas 2154 (Consolidated) | U6: Lojas/m2 | W6: =W14/W7 -> 0.0097299116 | X6: =X14/X7 -> 0.0096829697 | Y6: =Y14/Y7 -> 0.0096362543 | Z6: =Z14/Z7 -> 0.0095897643 | AA6: =AA14/AA7 -> 0.0095434986 | AB6: =AB14/AB7 -> 0.009497456 | AC6: =AC14/AC7 -> 0.0094516356 | AD6: =AD14/AD7 -> 0.0094060363 | ... AU6: =AU14/AU7 -> 0.0086636559
B7: Área (m²) | C7: Area (sqm) | D7: 190246.19 | E7: 192878.71 | F7: 193838.35 | G7: 199148.05 | H7: 198106.78 | I7: 198884.9 | J7: 199925.68 | K7: 206225.3 | L7: 204180.11 | M7: 206838.53 | N7: 205874.86 | O7: 211108.63 | P7: 209717.37 | Q7: 208451.97 | R7: 207935.27 | U7: =((R7/D7)^(1/15))-1 -> 0.0059447915 | W7: =R7*(1+U$7) -> 209171.4 | X7: =W7*(1+$U$7) -> 210414.88 | Y7: =X7*(1+$U$7) -> 211665.76 | Z7: =Y7*(1+$U$7) -> 212924.06 | AA7: =Z7*(1+$U$7) -> 214189.85 | AB7: =AA7*(1+$U$7) -> 215463.17 | AC7: =AB7*(1+$U$7) -> 216744.05 | AD7: =AC7*(1+$U$7) -> 218032.55 | AE7: =AD7*(1+$U$7) -> 219328.71 | ... AU7: =AT7*(1+$U$7) -> 241146.98
B8: Área (m²) - Continuadas | C8: Area (sqm) - Continued brands | D8: 189301.16 | E8: 191862.33 | F8: 192821.97 | G8: 197690.89 | H8: 196817.67 | I8: 197502.46 | J8: 198594.24 | K8: 204473.32 | L8: 202593.13 | M8: 205120.66 | N8: 204247.57 | O8: 209439.43 | P8: 209013.66 | Q8: 208323.11 | R8: 207935.27
B9: Lojas Próprias | C9: Owned Stores | D9: 71157.76 | E9: 73140.87 | F9: 73884.31 | G9: 76149.23 | H9: 76523.53 | I9: 77878.29 | J9: 78983.72 | K9: 83226.25 | L9: 83200.83 | M9: 85162.6 | N9: 84770.47 | O9: 87793.57 | P9: 87727.54 | Q9: 87889.53 | R9: 87687.91
B10: Franquias | C10: Franchises | D10: 118143.4 | E10: 118721.46 | F10: 118937.66 | G10: 121541.66 | H10: 120294.14 | I10: 119624.17 | J10: 119610.52 | K10: 121247.07 | L10: 119392.3 | M10: 119958.06 | N10: 119477.1 | O10: 121645.86 | P10: 121286.12 | Q10: 120433.58 | R10: 120247.36
B11: Área (m²) - Descontinuadas | C11: Area (sqm) - Discontinued brands | D11: 945.03 | E11: 1016.38 | F11: 1016.38 | G11: 1457.16 | H11: 1289.11 | I11: 1382.44 | J11: 1331.44 | K11: 1751.98 | L11: 1586.98 | M11: 1717.87 | N11: 1627.29 | O11: 1669.2 | P11: 703.71 | Q11: 128.86 | R11: 0
B12: Lojas Próprias - Descontinuadas | C12: Owned Stores | D12: 945.03 | E12: 1016.38 | F12: 1016.38 | G12: 1406.16 | H12: 1238.11 | I12: 1331.44 | J12: 1331.44 | K12: 1743.63 | L12: 1578.63 | M12: 1709.52 | N12: 1627.29 | O12: 1627.29 | P12: 703.71 | Q12: 128.86 | R12: 0
B13: Franquias - Descontinuadas | C13: Franchises | D13: 0 | E13: 0 | F13: 0 | G13: 51 | H13: 51 | I13: 51 | J13: 0 | K13: 8.35 | L13: 8.35 | M13: 8.35 | N13: 0 | O13: 41.91 | P13: 0 | Q13: 0 | R13: 0
B14: Número de Lojas | C14: Number of Stores | D14: 2000 | E14: 2023 | F14: 2032 | G14: 2106 | H14: 2076 | I14: 2071 | J14: 2068 | K14: 2130 | L14: 2091 | M14: 2095 | N14: 2087 | O14: 2129 | P14: 2086 | Q14: 2061 | R14: 2033 | U14: =((R14/D14)^(1/15))-1 -> 0.001091619 | W14: =R14*(1+U14) -> 2035.2193 | X14: =W14*(1+$U$14) -> 2037.4409 | Y14: =X14*(1+$U$14) -> 2039.6651 | Z14: =Y14*(1+$U$14) -> 2041.8916 | AA14: =Z14*(1+$U$14) -> 2044.1206 | AB14: =AA14*(1+$U$14) -> 2046.352 | AC14: =AB14*(1+$U$14) -> 2048.5858 | AD14: =AC14*(1+$U$14) -> 2050.8221 | AE14: =AD14*(1+$U$14) -> 2053.0608 | ... AU14: =AT14*(1+$U$14) -> 2089.2144
B15: Número de Lojas -Continuadas | C15: Number of Stores - Continued brands | D15: 1993 | E15: 2015 | F15: 2024 | G15: 2092 | H15: 2064 | I15: 2058 | J15: 2056 | K15: 2112 | L15: 2074 | M15: 2076 | N15: 2070 | O15: 2111 | P15: 2076 | Q15: 2059 | R15: 2033
B16: Lojas Próprias | C16: Owned Stores | D16: 484 | E16: 502 | F16: 506 | G16: 527 | H16: 524 | I16: 532 | J16: 538 | K16: 565 | L16: 561 | M16: 561 | N16: 562 | O16: 579 | P16: 564 | Q16: 560 | R16: 560
B17: Franquias | C17: Franchises | D17: 1477 | E17: 1481 | F17: 1485 | G17: 1532 | H17: 1507 | I17: 1492 | J17: 1484 | K17: 1514 | L17: 1480 | M17: 1479 | N17: 1471 | O17: 1494 | P17: 1470 | Q17: 1451 | R17: 1424
B18: Internacional | C18: Internacional | D18: 32 | E18: 32 | F18: 33 | G18: 33 | H18: 33 | I18: 34 | J18: 34 | K18: 33 | L18: 33 | M18: 36 | N18: 37 | O18: 38 | P18: 42 | Q18: 48 | R18: 49
B19: Número de Lojas - Descontinuadas | C19: Number of Stores - Discontinued brands | D19: 7 | E19: 8 | F19: 8 | G19: 14 | H19: 12 | I19: 13 | J19: 12 | K19: 18 | L19: 17 | M19: 19 | N19: 17 | O19: 18 | P19: 10 | Q19: 2 | R19: 0
B20: Lojas Próprias | C20: Owned Stores | D20: 7 | E20: 8 | F20: 8 | G20: 13 | H20: 11 | I20: 12 | J20: 12 | K20: 17 | L20: 16 | M20: 18 | N20: 17 | O20: 17 | P20: 10 | Q20: 2 | R20: 0
B21: Franquias | C21: Franchises | D21: 0 | E21: 0 | F21: 0 | G21: 1 | H21: 1 | I21: 1 | J21: 0 | K21: 1 | L21: 1 | M21: 1 | N21: 0 | O21: 1 | P21: 0 | Q21: 0 | R21: 0
B23: Shoes & Bags | C23: Shoes & Bags | U23: Lojas/m2 | W23: =W31/W24 -> 0.018305332 | X23: =X31/X24 -> 0.018317541 | Y23: =Y31/Y24 -> 0.018329757 | Z23: =Z31/Z24 -> 0.018341982 | AA23: =AA31/AA24 -> 0.018354215 | AB23: =AB31/AB24 -> 0.018366456 | AC23: =AC31/AC24 -> 0.018378705 | AD23: =AD31/AD24 -> 0.018390963 | ... AU23: =AU31/AU24 -> 0.018600594
B24: Área (m²) | C24: Area (sqm) | D24: 43288.37 | E24: 44033.89 | F24: 44112.07 | G24: 44840.34 | H24: 44566.17 | I24: 45222.2 | J24: 45068.37 | K24: 46162.16 | L24: 45619.44 | M24: 45750.35 | N24: 45719.16 | O24: 47019.12 | P24: 45843.4 | Q24: 45576.72 | R24: 45481.55 | U24: =((R24/D24)^(1/15))-1 -> 0.0033002834 | W24: =R24*(1+U24) -> 45631.652 | X24: =W24*(1+$U$24) -> 45782.249 | Y24: =X24*(1+$U$24) -> 45933.344 | Z24: =Y24*(1+$U$24) -> 46084.937 | AA24: =Z24*(1+$U$24) -> 46237.03 | AB24: =AA24*(1+$U$24) -> 46389.625 | AC24: =AB24*(1+$U$24) -> 46542.724 | AD24: =AC24*(1+$U$24) -> 46696.329 | AE24: =AD24*(1+$U$24) -> 46850.44 | ... AU24: =AT24*(1+$U$24) -> 49386.543
B25: Área (m²) - Continuadas | C25: Area (sqm) - Continued brands | D25: 42804.55 | E25: 43550.07 | F25: 43628.25 | G25: 44305.52 | H25: 44199.4 | I25: 44855.43 | J25: 44752.6 | K25: 45838.04 | L25: 45295.32 | M25: 45426.23 | N25: 45403.39 | O25: 46703.35 | P25: 45843.4 | Q25: 45576.72 | R25: 45481.55
B26: Lojas Próprias | C26: Owned Stores | D26: 5815.6 | E26: 6358.83 | F26: 6385.29 | G26: 6574.14 | H26: 6825.54 | I26: 7577.83 | J26: 7266.65 | K26: 7427.17 | L26: 7404.22 | M26: 7429.45 | N26: 7520.87 | O26: 7837.87 | P26: 7353.1 | Q26: 7239.31 | R26: 7203.62
